/opt/conda/lib/python3.12/site-packages/torch/cuda/__init__.py:734: UserWarning: Can't initialize NVML
  warnings.warn("Can't initialize NVML")
No CUDA runtime is found, using CUDA_HOME='/usr/local/cuda'
Traceback (most recent call last):
  File "/opt/conda/bin/accelerate", line 8, in <module>
    sys.exit(main())
             ^^^^^^
  File "/opt/conda/lib/python3.12/site-packages/accelerate/commands/accelerate_cli.py", line 48, in main
    args.func(args)
  File "/opt/conda/lib/python3.12/site-packages/accelerate/commands/launch.py", line 1175, in launch_command
    args, defaults, mp_from_config_flag = _validate_launch_command(args)
                                          ^^^^^^^^^^^^^^^^^^^^^^^^^^^^^^
  File "/opt/conda/lib/python3.12/site-packages/accelerate/commands/launch.py", line 1000, in _validate_launch_command
    defaults = load_config_from_file(args.config_file)
               ^^^^^^^^^^^^^^^^^^^^^^^^^^^^^^^^^^^^^^^
  File "/opt/conda/lib/python3.12/site-packages/accelerate/commands/config/config_args.py", line 72, in load_config_from_file
    return config_class.from_yaml_file(yaml_file=config_file)
           ^^^^^^^^^^^^^^^^^^^^^^^^^^^^^^^^^^^^^^^^^^^^^^^^^^
  File "/opt/conda/lib/python3.12/site-packages/accelerate/commands/config/config_args.py", line 156, in from_yaml_file
    raise ValueError(
ValueError: The config file at /home/iruizchicano/IFDL/config/config_cpubase.yaml had unknown keys (['batch_size', 'dataset_path']), please try upgrading your `accelerate` version or fix (and potentially remove) these keys from your config file.
INFO:    Terminating fuse-overlayfs after timeout
INFO:    Timeouts can be caused by a running background process
